2021-09-23 10:43:11,081 - 138724-MainThread - h:\HaoKe-Files\Codes\Crawl_items\utils\logger.py[line:23] - INFO: 123456
2021-09-23 11:17:00,958 - 137752-MainThread - h:\HaoKe-Files\Codes\Crawl_items\utils\send_req.py[line:46] - INFO: https://localhost:8880请求时出错:HTTPSConnectionPool(host='localhost', port=8880): Max retries exceeded with url: / (Caused by NewConnectionError('<urllib3.connection.HTTPSConnection object at 0x0000000005CBAC18>: Failed to establish a new connection: [WinError 10061] 由于目标计算机积极拒绝，无法连接。',))重试
2021-09-23 11:17:00,961 - 137752-MainThread - h:\HaoKe-Files\Codes\Crawl_items\utils\func_classes.py[line:23] - INFO: request第1次出现异常:track_func() got an unexpected keyword argument 'headers'
2021-09-23 11:17:05,970 - 137752-MainThread - h:\HaoKe-Files\Codes\Crawl_items\utils\send_req.py[line:46] - INFO: https://localhost:8880请求时出错:HTTPSConnectionPool(host='localhost', port=8880): Max retries exceeded with url: / (Caused by NewConnectionError('<urllib3.connection.HTTPSConnection object at 0x0000000005CEA320>: Failed to establish a new connection: [WinError 10061] 由于目标计算机积极拒绝，无法连接。',))重试
2021-09-23 11:17:05,971 - 137752-MainThread - h:\HaoKe-Files\Codes\Crawl_items\utils\func_classes.py[line:23] - INFO: request第3次出现异常:track_func() got an unexpected keyword argument 'headers'
2021-09-23 11:17:08,972 - 137752-MainThread - h:\HaoKe-Files\Codes\Crawl_items\utils\func_classes.py[line:33] - INFO: request放弃执行
2021-09-23 11:17:44,230 - 136128-MainThread - h:\HaoKe-Files\Codes\Crawl_items\utils\send_req.py[line:46] - INFO: https://localhost:8880请求时出错:HTTPSConnectionPool(host='localhost', port=8880): Max retries exceeded with url: / (Caused by NewConnectionError('<urllib3.connection.HTTPSConnection object at 0x0000000005C4AD68>: Failed to establish a new connection: [WinError 10061] 由于目标计算机积极拒绝，无法连接。',))重试
2021-09-23 11:17:44,233 - 136128-MainThread - h:\HaoKe-Files\Codes\Crawl_items\utils\func_classes.py[line:23] - INFO: request第1次出现异常:track_func() got an unexpected keyword argument 'headers'
2021-09-23 11:17:49,247 - 136128-MainThread - h:\HaoKe-Files\Codes\Crawl_items\utils\send_req.py[line:46] - INFO: https://localhost:8880请求时出错:HTTPSConnectionPool(host='localhost', port=8880): Max retries exceeded with url: / (Caused by NewConnectionError('<urllib3.connection.HTTPSConnection object at 0x0000000005C7B438>: Failed to establish a new connection: [WinError 10061] 由于目标计算机积极拒绝，无法连接。',))重试
2021-09-23 11:17:49,248 - 136128-MainThread - h:\HaoKe-Files\Codes\Crawl_items\utils\func_classes.py[line:23] - INFO: request第3次出现异常:track_func() got an unexpected keyword argument 'headers'
2021-09-23 11:17:52,248 - 136128-MainThread - h:\HaoKe-Files\Codes\Crawl_items\utils\func_classes.py[line:33] - INFO: request放弃执行
2021-09-23 11:18:40,696 - 138056-MainThread - h:\HaoKe-Files\Codes\Crawl_items\utils\send_req.py[line:46] - INFO: https://localhost:8880请求时出错:HTTPSConnectionPool(host='localhost', port=8880): Max retries exceeded with url: / (Caused by NewConnectionError('<urllib3.connection.HTTPSConnection object at 0x0000000005C5CCF8>: Failed to establish a new connection: [WinError 10061] 由于目标计算机积极拒绝，无法连接。',))重试
2021-09-23 11:18:42,701 - 138056-MainThread - h:\HaoKe-Files\Codes\Crawl_items\utils\send_req.py[line:46] - INFO: https://localhost:8880请求时出错:HTTPSConnectionPool(host='localhost', port=8880): Max retries exceeded with url: / (Caused by NewConnectionError('<urllib3.connection.HTTPSConnection object at 0x0000000005C8D3C8>: Failed to establish a new connection: [WinError 10061] 由于目标计算机积极拒绝，无法连接。',))重试
2021-09-23 11:18:44,713 - 138056-MainThread - h:\HaoKe-Files\Codes\Crawl_items\utils\send_req.py[line:46] - INFO: https://localhost:8880请求时出错:HTTPSConnectionPool(host='localhost', port=8880): Max retries exceeded with url: / (Caused by NewConnectionError('<urllib3.connection.HTTPSConnection object at 0x0000000005C8DB00>: Failed to establish a new connection: [WinError 10061] 由于目标计算机积极拒绝，无法连接。',))重试
2021-09-23 11:18:46,726 - 138056-MainThread - h:\HaoKe-Files\Codes\Crawl_items\utils\send_req.py[line:46] - INFO: https://localhost:8880请求时出错:HTTPSConnectionPool(host='localhost', port=8880): Max retries exceeded with url: / (Caused by NewConnectionError('<urllib3.connection.HTTPSConnection object at 0x0000000005C9A278>: Failed to establish a new connection: [WinError 10061] 由于目标计算机积极拒绝，无法连接。',))重试
2021-09-23 11:18:46,727 - 138056-MainThread - h:\HaoKe-Files\Codes\Crawl_items\utils\func_classes.py[line:33] - INFO: request放弃执行
2021-09-23 11:30:31,021 - 130832-MainThread - h:\HaoKe-Files\Codes\Crawl_items\utils\send_req.py[line:24] - INFO: https://localhost:8880请求时出错:HTTPSConnectionPool(host='localhost', port=8880): Max retries exceeded with url: / (Caused by NewConnectionError('<urllib3.connection.HTTPSConnection object at 0x0000000005FDEB70>: Failed to establish a new connection: [WinError 10061] 由于目标计算机积极拒绝，无法连接。',))重试
2021-09-23 11:30:33,030 - 130832-MainThread - h:\HaoKe-Files\Codes\Crawl_items\utils\send_req.py[line:24] - INFO: https://localhost:8880请求时出错:HTTPSConnectionPool(host='localhost', port=8880): Max retries exceeded with url: / (Caused by NewConnectionError('<urllib3.connection.HTTPSConnection object at 0x00000000060071D0>: Failed to establish a new connection: [WinError 10061] 由于目标计算机积极拒绝，无法连接。',))重试
2021-09-23 11:30:35,036 - 130832-MainThread - h:\HaoKe-Files\Codes\Crawl_items\utils\send_req.py[line:24] - INFO: https://localhost:8880请求时出错:HTTPSConnectionPool(host='localhost', port=8880): Max retries exceeded with url: / (Caused by NewConnectionError('<urllib3.connection.HTTPSConnection object at 0x0000000006007898>: Failed to establish a new connection: [WinError 10061] 由于目标计算机积极拒绝，无法连接。',))重试
2021-09-23 11:30:37,046 - 130832-MainThread - h:\HaoKe-Files\Codes\Crawl_items\utils\send_req.py[line:24] - INFO: https://localhost:8880请求时出错:HTTPSConnectionPool(host='localhost', port=8880): Max retries exceeded with url: / (Caused by NewConnectionError('<urllib3.connection.HTTPSConnection object at 0x0000000006007F98>: Failed to establish a new connection: [WinError 10061] 由于目标计算机积极拒绝，无法连接。',))重试
2021-09-23 11:30:39,058 - 130832-MainThread - h:\HaoKe-Files\Codes\Crawl_items\utils\send_req.py[line:24] - INFO: https://localhost:8880请求时出错:HTTPSConnectionPool(host='localhost', port=8880): Max retries exceeded with url: / (Caused by NewConnectionError('<urllib3.connection.HTTPSConnection object at 0x00000000060146D8>: Failed to establish a new connection: [WinError 10061] 由于目标计算机积极拒绝，无法连接。',))重试
2021-09-23 11:30:41,071 - 130832-MainThread - h:\HaoKe-Files\Codes\Crawl_items\utils\send_req.py[line:24] - INFO: https://localhost:8880请求时出错:HTTPSConnectionPool(host='localhost', port=8880): Max retries exceeded with url: / (Caused by NewConnectionError('<urllib3.connection.HTTPSConnection object at 0x0000000006014DD8>: Failed to establish a new connection: [WinError 10061] 由于目标计算机积极拒绝，无法连接。',))重试
2021-09-23 11:30:43,076 - 130832-MainThread - h:\HaoKe-Files\Codes\Crawl_items\utils\send_req.py[line:24] - INFO: https://localhost:8880请求时出错:HTTPSConnectionPool(host='localhost', port=8880): Max retries exceeded with url: / (Caused by NewConnectionError('<urllib3.connection.HTTPSConnection object at 0x0000000006022518>: Failed to establish a new connection: [WinError 10061] 由于目标计算机积极拒绝，无法连接。',))重试
2021-09-23 11:30:45,091 - 130832-MainThread - h:\HaoKe-Files\Codes\Crawl_items\utils\send_req.py[line:24] - INFO: https://localhost:8880请求时出错:HTTPSConnectionPool(host='localhost', port=8880): Max retries exceeded with url: / (Caused by NewConnectionError('<urllib3.connection.HTTPSConnection object at 0x0000000006022C18>: Failed to establish a new connection: [WinError 10061] 由于目标计算机积极拒绝，无法连接。',))重试
2021-09-23 11:30:47,098 - 130832-MainThread - h:\HaoKe-Files\Codes\Crawl_items\utils\send_req.py[line:24] - INFO: https://localhost:8880请求时出错:HTTPSConnectionPool(host='localhost', port=8880): Max retries exceeded with url: / (Caused by NewConnectionError('<urllib3.connection.HTTPSConnection object at 0x000000000602F358>: Failed to establish a new connection: [WinError 10061] 由于目标计算机积极拒绝，无法连接。',))重试
2021-09-23 11:30:49,114 - 130832-MainThread - h:\HaoKe-Files\Codes\Crawl_items\utils\send_req.py[line:24] - INFO: https://localhost:8880请求时出错:HTTPSConnectionPool(host='localhost', port=8880): Max retries exceeded with url: / (Caused by NewConnectionError('<urllib3.connection.HTTPSConnection object at 0x000000000602FA58>: Failed to establish a new connection: [WinError 10061] 由于目标计算机积极拒绝，无法连接。',))重试
2021-09-23 11:30:51,123 - 130832-MainThread - h:\HaoKe-Files\Codes\Crawl_items\utils\send_req.py[line:24] - INFO: https://localhost:8880请求时出错:HTTPSConnectionPool(host='localhost', port=8880): Max retries exceeded with url: / (Caused by NewConnectionError('<urllib3.connection.HTTPSConnection object at 0x000000000603A198>: Failed to establish a new connection: [WinError 10061] 由于目标计算机积极拒绝，无法连接。',))重试
2021-09-23 11:30:53,131 - 130832-MainThread - h:\HaoKe-Files\Codes\Crawl_items\utils\send_req.py[line:24] - INFO: https://localhost:8880请求时出错:HTTPSConnectionPool(host='localhost', port=8880): Max retries exceeded with url: / (Caused by NewConnectionError('<urllib3.connection.HTTPSConnection object at 0x000000000603A898>: Failed to establish a new connection: [WinError 10061] 由于目标计算机积极拒绝，无法连接。',))重试
2021-09-23 11:41:33,143 - 139160-MainThread - h:\HaoKe-Files\Codes\Crawl_items\test.py[line:3] - ERROR: 出错
